[2017-02-28 07:27:20,068][404][<WSGIRequest: GET '/favicon.ico'>] Not Found: /favicon.ico
[2017-02-28 07:45:57,930][500][<WSGIRequest: GET '/admin/polls/question/'>] Internal Server Error: /admin/polls/question/
Traceback (most recent call last):
  File "/usr/local/lib/python2.7/dist-packages/django/core/handlers/exception.py", line 39, in inner
    response = get_response(request)
  File "/usr/local/lib/python2.7/dist-packages/django/core/handlers/base.py", line 217, in _get_response
    response = self.process_exception_by_middleware(e, request)
  File "/usr/local/lib/python2.7/dist-packages/django/core/handlers/base.py", line 215, in _get_response
    response = response.render()
  File "/usr/local/lib/python2.7/dist-packages/django/template/response.py", line 109, in render
    self.content = self.rendered_content
  File "/usr/local/lib/python2.7/dist-packages/django/template/response.py", line 86, in rendered_content
    content = template.render(context, self._request)
  File "/usr/local/lib/python2.7/dist-packages/django/template/backends/django.py", line 66, in render
    return self.template.render(context)
  File "/usr/local/lib/python2.7/dist-packages/django/template/base.py", line 208, in render
    return self._render(context)
  File "/usr/local/lib/python2.7/dist-packages/django/template/base.py", line 199, in _render
    return self.nodelist.render(context)
  File "/usr/local/lib/python2.7/dist-packages/django/template/base.py", line 994, in render
    bit = node.render_annotated(context)
  File "/usr/local/lib/python2.7/dist-packages/django/template/base.py", line 961, in render_annotated
    return self.render(context)
  File "/usr/local/lib/python2.7/dist-packages/django/template/loader_tags.py", line 174, in render
    return compiled_parent._render(context)
  File "/usr/local/lib/python2.7/dist-packages/django/template/base.py", line 199, in _render
    return self.nodelist.render(context)
  File "/usr/local/lib/python2.7/dist-packages/django/template/base.py", line 994, in render
    bit = node.render_annotated(context)
  File "/usr/local/lib/python2.7/dist-packages/django/template/base.py", line 961, in render_annotated
    return self.render(context)
  File "/usr/local/lib/python2.7/dist-packages/django/template/loader_tags.py", line 174, in render
    return compiled_parent._render(context)
  File "/usr/local/lib/python2.7/dist-packages/django/template/base.py", line 199, in _render
    return self.nodelist.render(context)
  File "/usr/local/lib/python2.7/dist-packages/django/template/base.py", line 994, in render
    bit = node.render_annotated(context)
  File "/usr/local/lib/python2.7/dist-packages/django/template/base.py", line 961, in render_annotated
    return self.render(context)
  File "/usr/local/lib/python2.7/dist-packages/django/template/loader_tags.py", line 70, in render
    result = block.nodelist.render(context)
  File "/usr/local/lib/python2.7/dist-packages/django/template/base.py", line 994, in render
    bit = node.render_annotated(context)
  File "/usr/local/lib/python2.7/dist-packages/django/template/base.py", line 961, in render_annotated
    return self.render(context)
  File "/usr/local/lib/python2.7/dist-packages/django/template/loader_tags.py", line 70, in render
    result = block.nodelist.render(context)
  File "/usr/local/lib/python2.7/dist-packages/django/template/base.py", line 994, in render
    bit = node.render_annotated(context)
  File "/usr/local/lib/python2.7/dist-packages/django/template/base.py", line 961, in render_annotated
    return self.render(context)
  File "/usr/local/lib/python2.7/dist-packages/django/template/library.py", line 225, in render
    _dict = self.func(*resolved_args, **resolved_kwargs)
  File "/usr/local/lib/python2.7/dist-packages/django/contrib/admin/templatetags/admin_list.py", line 339, in result_list
    'results': list(results(cl))}
  File "/usr/local/lib/python2.7/dist-packages/django/contrib/admin/templatetags/admin_list.py", line 315, in results
    yield ResultList(None, items_for_result(cl, res, None))
  File "/usr/local/lib/python2.7/dist-packages/django/contrib/admin/templatetags/admin_list.py", line 306, in __init__
    super(ResultList, self).__init__(*items)
  File "/usr/local/lib/python2.7/dist-packages/django/contrib/admin/templatetags/admin_list.py", line 217, in items_for_result
    f, attr, value = lookup_field(field_name, result, cl.model_admin)
  File "/usr/local/lib/python2.7/dist-packages/django/contrib/admin/utils.py", line 290, in lookup_field
    value = attr()
  File "/usr/local/lib/python2.7/dist-packages/django/utils/six.py", line 842, in <lambda>
    klass.__str__ = lambda self: self.__unicode__().encode('utf-8')
  File "/root/PycharmProjects/untitled1/polls/models.py", line 15, in __str__
    return self.question_text
AttributeError: 'Question' object has no attribute 'question_text'
[2017-02-28 08:09:50,220][404][<WSGIRequest: GET '/'>] Not Found: /
[2017-02-28 08:10:13,132][404][<WSGIRequest: GET '/polls/3/'>] Not Found: /polls/3/
[2017-02-28 08:37:43,324][500][<WSGIRequest: GET '/latest.html'>] Internal Server Error: /latest.html
Traceback (most recent call last):
  File "/usr/local/lib/python2.7/dist-packages/django/core/handlers/exception.py", line 39, in inner
    response = get_response(request)
  File "/usr/local/lib/python2.7/dist-packages/django/core/handlers/base.py", line 187, in _get_response
    response = self.process_exception_by_middleware(e, request)
  File "/usr/local/lib/python2.7/dist-packages/django/core/handlers/base.py", line 185, in _get_response
    response = wrapped_callback(request, *callback_args, **callback_kwargs)
  File "/root/PycharmProjects/untitled1/polls/views.py", line 12, in index
    question_obj = Question.objects.get(pk=1)
  File "/usr/local/lib/python2.7/dist-packages/django/db/models/manager.py", line 85, in manager_method
    return getattr(self.get_queryset(), name)(*args, **kwargs)
  File "/usr/local/lib/python2.7/dist-packages/django/db/models/query.py", line 385, in get
    self.model._meta.object_name
DoesNotExist: Question matching query does not exist.
[2017-02-28 08:38:30,172][500][<WSGIRequest: GET '/latest.html'>] Internal Server Error: /latest.html
Traceback (most recent call last):
  File "/usr/local/lib/python2.7/dist-packages/django/core/handlers/exception.py", line 39, in inner
    response = get_response(request)
  File "/usr/local/lib/python2.7/dist-packages/django/core/handlers/base.py", line 187, in _get_response
    response = self.process_exception_by_middleware(e, request)
  File "/usr/local/lib/python2.7/dist-packages/django/core/handlers/base.py", line 185, in _get_response
    response = wrapped_callback(request, *callback_args, **callback_kwargs)
  File "/root/PycharmProjects/untitled1/polls/views.py", line 16, in index
    return render(request,'index.html',context={'form',question_form})
  File "/usr/local/lib/python2.7/dist-packages/django/shortcuts.py", line 30, in render
    content = loader.render_to_string(template_name, context, request, using=using)
  File "/usr/local/lib/python2.7/dist-packages/django/template/loader.py", line 68, in render_to_string
    return template.render(context, request)
  File "/usr/local/lib/python2.7/dist-packages/django/template/backends/django.py", line 64, in render
    context = make_context(context, request, autoescape=self.backend.engine.autoescape)
  File "/usr/local/lib/python2.7/dist-packages/django/template/context.py", line 267, in make_context
    context.push(original_context)
  File "/usr/local/lib/python2.7/dist-packages/django/template/context.py", line 59, in push
    return ContextDict(self, *dicts, **kwargs)
  File "/usr/local/lib/python2.7/dist-packages/django/template/context.py", line 18, in __init__
    super(ContextDict, self).__init__(*args, **kwargs)
ValueError: dictionary update sequence element #0 has length 1; 2 is required
[2017-02-28 08:39:20,527][500][<WSGIRequest: GET '/latest.html'>] Internal Server Error: /latest.html
Traceback (most recent call last):
  File "/usr/local/lib/python2.7/dist-packages/django/core/handlers/exception.py", line 39, in inner
    response = get_response(request)
  File "/usr/local/lib/python2.7/dist-packages/django/core/handlers/base.py", line 187, in _get_response
    response = self.process_exception_by_middleware(e, request)
  File "/usr/local/lib/python2.7/dist-packages/django/core/handlers/base.py", line 185, in _get_response
    response = wrapped_callback(request, *callback_args, **callback_kwargs)
  File "/root/PycharmProjects/untitled1/polls/views.py", line 16, in index
    return render(request,'index.html',{'form',question_form})
  File "/usr/local/lib/python2.7/dist-packages/django/shortcuts.py", line 30, in render
    content = loader.render_to_string(template_name, context, request, using=using)
  File "/usr/local/lib/python2.7/dist-packages/django/template/loader.py", line 68, in render_to_string
    return template.render(context, request)
  File "/usr/local/lib/python2.7/dist-packages/django/template/backends/django.py", line 64, in render
    context = make_context(context, request, autoescape=self.backend.engine.autoescape)
  File "/usr/local/lib/python2.7/dist-packages/django/template/context.py", line 267, in make_context
    context.push(original_context)
  File "/usr/local/lib/python2.7/dist-packages/django/template/context.py", line 59, in push
    return ContextDict(self, *dicts, **kwargs)
  File "/usr/local/lib/python2.7/dist-packages/django/template/context.py", line 18, in __init__
    super(ContextDict, self).__init__(*args, **kwargs)
ValueError: dictionary update sequence element #0 has length 1; 2 is required
[2017-02-28 08:42:40,021][500][<WSGIRequest: GET '/latest.html'>] Internal Server Error: /latest.html
Traceback (most recent call last):
  File "/usr/local/lib/python2.7/dist-packages/django/core/handlers/exception.py", line 39, in inner
    response = get_response(request)
  File "/usr/local/lib/python2.7/dist-packages/django/core/handlers/base.py", line 187, in _get_response
    response = self.process_exception_by_middleware(e, request)
  File "/usr/local/lib/python2.7/dist-packages/django/core/handlers/base.py", line 185, in _get_response
    response = wrapped_callback(request, *callback_args, **callback_kwargs)
  File "/root/PycharmProjects/untitled1/polls/views.py", line 16, in index
    return render(request,'index.html',{'form',question_form})
  File "/usr/local/lib/python2.7/dist-packages/django/shortcuts.py", line 30, in render
    content = loader.render_to_string(template_name, context, request, using=using)
  File "/usr/local/lib/python2.7/dist-packages/django/template/loader.py", line 68, in render_to_string
    return template.render(context, request)
  File "/usr/local/lib/python2.7/dist-packages/django/template/backends/django.py", line 64, in render
    context = make_context(context, request, autoescape=self.backend.engine.autoescape)
  File "/usr/local/lib/python2.7/dist-packages/django/template/context.py", line 267, in make_context
    context.push(original_context)
  File "/usr/local/lib/python2.7/dist-packages/django/template/context.py", line 59, in push
    return ContextDict(self, *dicts, **kwargs)
  File "/usr/local/lib/python2.7/dist-packages/django/template/context.py", line 18, in __init__
    super(ContextDict, self).__init__(*args, **kwargs)
ValueError: dictionary update sequence element #0 has length 1; 2 is required
[2017-02-28 08:43:33,556][500][<WSGIRequest: GET '/latest.html'>] Internal Server Error: /latest.html
Traceback (most recent call last):
  File "/usr/local/lib/python2.7/dist-packages/django/core/handlers/exception.py", line 39, in inner
    response = get_response(request)
  File "/usr/local/lib/python2.7/dist-packages/django/core/handlers/base.py", line 187, in _get_response
    response = self.process_exception_by_middleware(e, request)
  File "/usr/local/lib/python2.7/dist-packages/django/core/handlers/base.py", line 185, in _get_response
    response = wrapped_callback(request, *callback_args, **callback_kwargs)
  File "/root/PycharmProjects/untitled1/polls/views.py", line 16, in index
    return render(request,'index.html',{'form',question_form})
  File "/usr/local/lib/python2.7/dist-packages/django/shortcuts.py", line 30, in render
    content = loader.render_to_string(template_name, context, request, using=using)
  File "/usr/local/lib/python2.7/dist-packages/django/template/loader.py", line 68, in render_to_string
    return template.render(context, request)
  File "/usr/local/lib/python2.7/dist-packages/django/template/backends/django.py", line 64, in render
    context = make_context(context, request, autoescape=self.backend.engine.autoescape)
  File "/usr/local/lib/python2.7/dist-packages/django/template/context.py", line 267, in make_context
    context.push(original_context)
  File "/usr/local/lib/python2.7/dist-packages/django/template/context.py", line 59, in push
    return ContextDict(self, *dicts, **kwargs)
  File "/usr/local/lib/python2.7/dist-packages/django/template/context.py", line 18, in __init__
    super(ContextDict, self).__init__(*args, **kwargs)
ValueError: dictionary update sequence element #0 has length 1; 2 is required
[2017-02-28 08:51:28,271][403][<WSGIRequest: POST '/latest.html'>] Forbidden (CSRF token missing or incorrect.): /latest.html
[2017-02-28 09:08:31,040][404][<WSGIRequest: GET '/'>] Not Found: /
[2017-02-28 09:08:36,700][404][<WSGIRequest: GET '/favicon.ico'>] Not Found: /favicon.ico
[2017-03-01 02:36:52,054][500][<WSGIRequest: POST '/'>] Internal Server Error: /
Traceback (most recent call last):
  File "/usr/local/lib/python2.7/dist-packages/django/core/handlers/exception.py", line 39, in inner
    response = get_response(request)
  File "/usr/local/lib/python2.7/dist-packages/django/core/handlers/base.py", line 187, in _get_response
    response = self.process_exception_by_middleware(e, request)
  File "/usr/local/lib/python2.7/dist-packages/django/core/handlers/base.py", line 185, in _get_response
    response = wrapped_callback(request, *callback_args, **callback_kwargs)
  File "/root/PycharmProjects/untitled1/polls/views.py", line 17, in index
    if form.is_valid():
  File "/usr/local/lib/python2.7/dist-packages/django/forms/forms.py", line 169, in is_valid
    return self.is_bound and not self.errors
  File "/usr/local/lib/python2.7/dist-packages/django/forms/forms.py", line 161, in errors
    self.full_clean()
  File "/usr/local/lib/python2.7/dist-packages/django/forms/forms.py", line 370, in full_clean
    self._clean_fields()
  File "/usr/local/lib/python2.7/dist-packages/django/forms/forms.py", line 391, in _clean_fields
    value = getattr(self, 'clean_%s' % name)()
  File "/root/PycharmProjects/untitled1/polls/forms.py", line 60, in clean_host_list
    host_count = Host.objects.filter(name=self.cleaned_data["server_name"]).count()
KeyError: 'server_name'
[2017-03-01 02:37:57,959][500][<WSGIRequest: POST '/'>] Internal Server Error: /
Traceback (most recent call last):
  File "/usr/local/lib/python2.7/dist-packages/django/core/handlers/exception.py", line 39, in inner
    response = get_response(request)
  File "/usr/local/lib/python2.7/dist-packages/django/core/handlers/base.py", line 187, in _get_response
    response = self.process_exception_by_middleware(e, request)
  File "/usr/local/lib/python2.7/dist-packages/django/core/handlers/base.py", line 185, in _get_response
    response = wrapped_callback(request, *callback_args, **callback_kwargs)
  File "/root/PycharmProjects/untitled1/polls/views.py", line 17, in index
    if form.is_valid():
  File "/usr/local/lib/python2.7/dist-packages/django/forms/forms.py", line 169, in is_valid
    return self.is_bound and not self.errors
  File "/usr/local/lib/python2.7/dist-packages/django/forms/forms.py", line 161, in errors
    self.full_clean()
  File "/usr/local/lib/python2.7/dist-packages/django/forms/forms.py", line 370, in full_clean
    self._clean_fields()
  File "/usr/local/lib/python2.7/dist-packages/django/forms/forms.py", line 391, in _clean_fields
    value = getattr(self, 'clean_%s' % name)()
  File "/root/PycharmProjects/untitled1/polls/forms.py", line 60, in clean_host_list
    host_count = Host.objects.filter(name=self.cleaned_data["server_name"]).count()
KeyError: 'server_name'
[2017-03-01 02:38:06,992][500][<WSGIRequest: POST '/'>] Internal Server Error: /
Traceback (most recent call last):
  File "/usr/local/lib/python2.7/dist-packages/django/core/handlers/exception.py", line 39, in inner
    response = get_response(request)
  File "/usr/local/lib/python2.7/dist-packages/django/core/handlers/base.py", line 187, in _get_response
    response = self.process_exception_by_middleware(e, request)
  File "/usr/local/lib/python2.7/dist-packages/django/core/handlers/base.py", line 185, in _get_response
    response = wrapped_callback(request, *callback_args, **callback_kwargs)
  File "/root/PycharmProjects/untitled1/polls/views.py", line 17, in index
    if form.is_valid():
  File "/usr/local/lib/python2.7/dist-packages/django/forms/forms.py", line 169, in is_valid
    return self.is_bound and not self.errors
  File "/usr/local/lib/python2.7/dist-packages/django/forms/forms.py", line 161, in errors
    self.full_clean()
  File "/usr/local/lib/python2.7/dist-packages/django/forms/forms.py", line 370, in full_clean
    self._clean_fields()
  File "/usr/local/lib/python2.7/dist-packages/django/forms/forms.py", line 391, in _clean_fields
    value = getattr(self, 'clean_%s' % name)()
  File "/root/PycharmProjects/untitled1/polls/forms.py", line 60, in clean_host_list
    host_count = Host.objects.filter(name=self.cleaned_data["server_name"]).count()
KeyError: 'server_name'
[2017-03-01 02:39:07,306][500][<WSGIRequest: POST '/'>] Internal Server Error: /
Traceback (most recent call last):
  File "/usr/local/lib/python2.7/dist-packages/django/core/handlers/exception.py", line 39, in inner
    response = get_response(request)
  File "/usr/local/lib/python2.7/dist-packages/django/core/handlers/base.py", line 187, in _get_response
    response = self.process_exception_by_middleware(e, request)
  File "/usr/local/lib/python2.7/dist-packages/django/core/handlers/base.py", line 185, in _get_response
    response = wrapped_callback(request, *callback_args, **callback_kwargs)
  File "/root/PycharmProjects/untitled1/polls/views.py", line 17, in index
    if form.is_valid():
  File "/usr/local/lib/python2.7/dist-packages/django/forms/forms.py", line 169, in is_valid
    return self.is_bound and not self.errors
  File "/usr/local/lib/python2.7/dist-packages/django/forms/forms.py", line 161, in errors
    self.full_clean()
  File "/usr/local/lib/python2.7/dist-packages/django/forms/forms.py", line 370, in full_clean
    self._clean_fields()
  File "/usr/local/lib/python2.7/dist-packages/django/forms/forms.py", line 391, in _clean_fields
    value = getattr(self, 'clean_%s' % name)()
  File "/root/PycharmProjects/untitled1/polls/forms.py", line 61, in clean_host_list
    host_count = Host.objects.filter(name=self.cleaned_data["server_name"]).count()
KeyError: 'server_name'
[2017-03-01 02:39:35,430][500][<WSGIRequest: POST '/'>] Internal Server Error: /
Traceback (most recent call last):
  File "/usr/local/lib/python2.7/dist-packages/django/core/handlers/exception.py", line 39, in inner
    response = get_response(request)
  File "/usr/local/lib/python2.7/dist-packages/django/core/handlers/base.py", line 187, in _get_response
    response = self.process_exception_by_middleware(e, request)
  File "/usr/local/lib/python2.7/dist-packages/django/core/handlers/base.py", line 185, in _get_response
    response = wrapped_callback(request, *callback_args, **callback_kwargs)
  File "/root/PycharmProjects/untitled1/polls/views.py", line 17, in index
    if form.is_valid():
  File "/usr/local/lib/python2.7/dist-packages/django/forms/forms.py", line 169, in is_valid
    return self.is_bound and not self.errors
  File "/usr/local/lib/python2.7/dist-packages/django/forms/forms.py", line 161, in errors
    self.full_clean()
  File "/usr/local/lib/python2.7/dist-packages/django/forms/forms.py", line 370, in full_clean
    self._clean_fields()
  File "/usr/local/lib/python2.7/dist-packages/django/forms/forms.py", line 391, in _clean_fields
    value = getattr(self, 'clean_%s' % name)()
  File "/root/PycharmProjects/untitled1/polls/forms.py", line 61, in clean_host_list
    host_count = Host.objects.filter(name=self.cleaned_data["server_name"]).count()
KeyError: 'server_name'
[2017-03-01 02:51:10,813][500][<WSGIRequest: POST '/'>] Internal Server Error: /
Traceback (most recent call last):
  File "/usr/local/lib/python2.7/dist-packages/django/core/handlers/exception.py", line 39, in inner
    response = get_response(request)
  File "/usr/local/lib/python2.7/dist-packages/django/core/handlers/base.py", line 187, in _get_response
    response = self.process_exception_by_middleware(e, request)
  File "/usr/local/lib/python2.7/dist-packages/django/core/handlers/base.py", line 185, in _get_response
    response = wrapped_callback(request, *callback_args, **callback_kwargs)
  File "/root/PycharmProjects/untitled1/polls/views.py", line 30, in index
    return render(request, 'index.html', {'form': form})
  File "/usr/local/lib/python2.7/dist-packages/django/shortcuts.py", line 30, in render
    content = loader.render_to_string(template_name, context, request, using=using)
  File "/usr/local/lib/python2.7/dist-packages/django/template/loader.py", line 67, in render_to_string
    template = get_template(template_name, using=using)
  File "/usr/local/lib/python2.7/dist-packages/django/template/loader.py", line 21, in get_template
    return engine.get_template(template_name)
  File "/usr/local/lib/python2.7/dist-packages/django/template/backends/django.py", line 39, in get_template
    return Template(self.engine.get_template(template_name), self)
  File "/usr/local/lib/python2.7/dist-packages/django/template/engine.py", line 160, in get_template
    template, origin = self.find_template(template_name)
  File "/usr/local/lib/python2.7/dist-packages/django/template/engine.py", line 134, in find_template
    name, template_dirs=dirs, skip=skip,
  File "/usr/local/lib/python2.7/dist-packages/django/template/loaders/base.py", line 44, in get_template
    contents, origin, origin.template_name, self.engine,
  File "/usr/local/lib/python2.7/dist-packages/django/template/base.py", line 191, in __init__
    self.nodelist = self.compile_nodelist()
  File "/usr/local/lib/python2.7/dist-packages/django/template/base.py", line 233, in compile_nodelist
    return parser.parse()
  File "/usr/local/lib/python2.7/dist-packages/django/template/base.py", line 489, in parse
    raise self.error(token, e)
TemplateSyntaxError: Variables and attributes may not begin with underscores: 'form.__all__.0'
[2017-03-01 02:52:17,408][500][<WSGIRequest: POST '/'>] Internal Server Error: /
Traceback (most recent call last):
  File "/usr/local/lib/python2.7/dist-packages/django/core/handlers/exception.py", line 39, in inner
    response = get_response(request)
  File "/usr/local/lib/python2.7/dist-packages/django/core/handlers/base.py", line 187, in _get_response
    response = self.process_exception_by_middleware(e, request)
  File "/usr/local/lib/python2.7/dist-packages/django/core/handlers/base.py", line 185, in _get_response
    response = wrapped_callback(request, *callback_args, **callback_kwargs)
  File "/root/PycharmProjects/untitled1/polls/views.py", line 30, in index
    return render(request, 'index.html', {'form': form})
  File "/usr/local/lib/python2.7/dist-packages/django/shortcuts.py", line 30, in render
    content = loader.render_to_string(template_name, context, request, using=using)
  File "/usr/local/lib/python2.7/dist-packages/django/template/loader.py", line 67, in render_to_string
    template = get_template(template_name, using=using)
  File "/usr/local/lib/python2.7/dist-packages/django/template/loader.py", line 21, in get_template
    return engine.get_template(template_name)
  File "/usr/local/lib/python2.7/dist-packages/django/template/backends/django.py", line 39, in get_template
    return Template(self.engine.get_template(template_name), self)
  File "/usr/local/lib/python2.7/dist-packages/django/template/engine.py", line 160, in get_template
    template, origin = self.find_template(template_name)
  File "/usr/local/lib/python2.7/dist-packages/django/template/engine.py", line 134, in find_template
    name, template_dirs=dirs, skip=skip,
  File "/usr/local/lib/python2.7/dist-packages/django/template/loaders/base.py", line 44, in get_template
    contents, origin, origin.template_name, self.engine,
  File "/usr/local/lib/python2.7/dist-packages/django/template/base.py", line 191, in __init__
    self.nodelist = self.compile_nodelist()
  File "/usr/local/lib/python2.7/dist-packages/django/template/base.py", line 233, in compile_nodelist
    return parser.parse()
  File "/usr/local/lib/python2.7/dist-packages/django/template/base.py", line 489, in parse
    raise self.error(token, e)
TemplateSyntaxError: Variables and attributes may not begin with underscores: 'form.errors.__all__.0'
[2017-03-01 02:52:39,043][500][<WSGIRequest: POST '/'>] Internal Server Error: /
Traceback (most recent call last):
  File "/usr/local/lib/python2.7/dist-packages/django/core/handlers/exception.py", line 39, in inner
    response = get_response(request)
  File "/usr/local/lib/python2.7/dist-packages/django/core/handlers/base.py", line 187, in _get_response
    response = self.process_exception_by_middleware(e, request)
  File "/usr/local/lib/python2.7/dist-packages/django/core/handlers/base.py", line 185, in _get_response
    response = wrapped_callback(request, *callback_args, **callback_kwargs)
  File "/root/PycharmProjects/untitled1/polls/views.py", line 30, in index
    return render(request, 'index.html', {'form': form})
  File "/usr/local/lib/python2.7/dist-packages/django/shortcuts.py", line 30, in render
    content = loader.render_to_string(template_name, context, request, using=using)
  File "/usr/local/lib/python2.7/dist-packages/django/template/loader.py", line 67, in render_to_string
    template = get_template(template_name, using=using)
  File "/usr/local/lib/python2.7/dist-packages/django/template/loader.py", line 21, in get_template
    return engine.get_template(template_name)
  File "/usr/local/lib/python2.7/dist-packages/django/template/backends/django.py", line 39, in get_template
    return Template(self.engine.get_template(template_name), self)
  File "/usr/local/lib/python2.7/dist-packages/django/template/engine.py", line 160, in get_template
    template, origin = self.find_template(template_name)
  File "/usr/local/lib/python2.7/dist-packages/django/template/engine.py", line 134, in find_template
    name, template_dirs=dirs, skip=skip,
  File "/usr/local/lib/python2.7/dist-packages/django/template/loaders/base.py", line 44, in get_template
    contents, origin, origin.template_name, self.engine,
  File "/usr/local/lib/python2.7/dist-packages/django/template/base.py", line 191, in __init__
    self.nodelist = self.compile_nodelist()
  File "/usr/local/lib/python2.7/dist-packages/django/template/base.py", line 233, in compile_nodelist
    return parser.parse()
  File "/usr/local/lib/python2.7/dist-packages/django/template/base.py", line 489, in parse
    raise self.error(token, e)
TemplateSyntaxError: Variables and attributes may not begin with underscores: 'form.errors.__all__.0'
[2017-03-01 02:53:22,300][500][<WSGIRequest: POST '/'>] Internal Server Error: /
Traceback (most recent call last):
  File "/usr/local/lib/python2.7/dist-packages/django/core/handlers/exception.py", line 39, in inner
    response = get_response(request)
  File "/usr/local/lib/python2.7/dist-packages/django/core/handlers/base.py", line 187, in _get_response
    response = self.process_exception_by_middleware(e, request)
  File "/usr/local/lib/python2.7/dist-packages/django/core/handlers/base.py", line 185, in _get_response
    response = wrapped_callback(request, *callback_args, **callback_kwargs)
  File "/root/PycharmProjects/untitled1/polls/views.py", line 30, in index
    return render(request, 'index.html', {'form': form})
  File "/usr/local/lib/python2.7/dist-packages/django/shortcuts.py", line 30, in render
    content = loader.render_to_string(template_name, context, request, using=using)
  File "/usr/local/lib/python2.7/dist-packages/django/template/loader.py", line 67, in render_to_string
    template = get_template(template_name, using=using)
  File "/usr/local/lib/python2.7/dist-packages/django/template/loader.py", line 21, in get_template
    return engine.get_template(template_name)
  File "/usr/local/lib/python2.7/dist-packages/django/template/backends/django.py", line 39, in get_template
    return Template(self.engine.get_template(template_name), self)
  File "/usr/local/lib/python2.7/dist-packages/django/template/engine.py", line 160, in get_template
    template, origin = self.find_template(template_name)
  File "/usr/local/lib/python2.7/dist-packages/django/template/engine.py", line 134, in find_template
    name, template_dirs=dirs, skip=skip,
  File "/usr/local/lib/python2.7/dist-packages/django/template/loaders/base.py", line 44, in get_template
    contents, origin, origin.template_name, self.engine,
  File "/usr/local/lib/python2.7/dist-packages/django/template/base.py", line 191, in __init__
    self.nodelist = self.compile_nodelist()
  File "/usr/local/lib/python2.7/dist-packages/django/template/base.py", line 233, in compile_nodelist
    return parser.parse()
  File "/usr/local/lib/python2.7/dist-packages/django/template/base.py", line 489, in parse
    raise self.error(token, e)
TemplateSyntaxError: Variables and attributes may not begin with underscores: 'form.errors.__all__.0'
[2017-03-01 02:53:30,115][500][<WSGIRequest: GET '/'>] Internal Server Error: /
Traceback (most recent call last):
  File "/usr/local/lib/python2.7/dist-packages/django/core/handlers/exception.py", line 39, in inner
    response = get_response(request)
  File "/usr/local/lib/python2.7/dist-packages/django/core/handlers/base.py", line 187, in _get_response
    response = self.process_exception_by_middleware(e, request)
  File "/usr/local/lib/python2.7/dist-packages/django/core/handlers/base.py", line 185, in _get_response
    response = wrapped_callback(request, *callback_args, **callback_kwargs)
  File "/root/PycharmProjects/untitled1/polls/views.py", line 30, in index
    return render(request, 'index.html', {'form': form})
  File "/usr/local/lib/python2.7/dist-packages/django/shortcuts.py", line 30, in render
    content = loader.render_to_string(template_name, context, request, using=using)
  File "/usr/local/lib/python2.7/dist-packages/django/template/loader.py", line 67, in render_to_string
    template = get_template(template_name, using=using)
  File "/usr/local/lib/python2.7/dist-packages/django/template/loader.py", line 21, in get_template
    return engine.get_template(template_name)
  File "/usr/local/lib/python2.7/dist-packages/django/template/backends/django.py", line 39, in get_template
    return Template(self.engine.get_template(template_name), self)
  File "/usr/local/lib/python2.7/dist-packages/django/template/engine.py", line 160, in get_template
    template, origin = self.find_template(template_name)
  File "/usr/local/lib/python2.7/dist-packages/django/template/engine.py", line 134, in find_template
    name, template_dirs=dirs, skip=skip,
  File "/usr/local/lib/python2.7/dist-packages/django/template/loaders/base.py", line 44, in get_template
    contents, origin, origin.template_name, self.engine,
  File "/usr/local/lib/python2.7/dist-packages/django/template/base.py", line 191, in __init__
    self.nodelist = self.compile_nodelist()
  File "/usr/local/lib/python2.7/dist-packages/django/template/base.py", line 233, in compile_nodelist
    return parser.parse()
  File "/usr/local/lib/python2.7/dist-packages/django/template/base.py", line 489, in parse
    raise self.error(token, e)
TemplateSyntaxError: Variables and attributes may not begin with underscores: 'form.errors.__all__.0'
[2017-03-01 02:59:30,273][500][<WSGIRequest: GET '/'>] Internal Server Error: /
Traceback (most recent call last):
  File "/usr/local/lib/python2.7/dist-packages/django/core/handlers/exception.py", line 39, in inner
    response = get_response(request)
  File "/usr/local/lib/python2.7/dist-packages/django/core/handlers/base.py", line 187, in _get_response
    response = self.process_exception_by_middleware(e, request)
  File "/usr/local/lib/python2.7/dist-packages/django/core/handlers/base.py", line 185, in _get_response
    response = wrapped_callback(request, *callback_args, **callback_kwargs)
  File "/root/PycharmProjects/untitled1/polls/views.py", line 30, in index
    return render(request, 'index.html', {'form': form})
  File "/usr/local/lib/python2.7/dist-packages/django/shortcuts.py", line 30, in render
    content = loader.render_to_string(template_name, context, request, using=using)
  File "/usr/local/lib/python2.7/dist-packages/django/template/loader.py", line 67, in render_to_string
    template = get_template(template_name, using=using)
  File "/usr/local/lib/python2.7/dist-packages/django/template/loader.py", line 21, in get_template
    return engine.get_template(template_name)
  File "/usr/local/lib/python2.7/dist-packages/django/template/backends/django.py", line 39, in get_template
    return Template(self.engine.get_template(template_name), self)
  File "/usr/local/lib/python2.7/dist-packages/django/template/engine.py", line 160, in get_template
    template, origin = self.find_template(template_name)
  File "/usr/local/lib/python2.7/dist-packages/django/template/engine.py", line 134, in find_template
    name, template_dirs=dirs, skip=skip,
  File "/usr/local/lib/python2.7/dist-packages/django/template/loaders/base.py", line 44, in get_template
    contents, origin, origin.template_name, self.engine,
  File "/usr/local/lib/python2.7/dist-packages/django/template/base.py", line 191, in __init__
    self.nodelist = self.compile_nodelist()
  File "/usr/local/lib/python2.7/dist-packages/django/template/base.py", line 233, in compile_nodelist
    return parser.parse()
  File "/usr/local/lib/python2.7/dist-packages/django/template/base.py", line 489, in parse
    raise self.error(token, e)
TemplateSyntaxError: Variables and attributes may not begin with underscores: 'form.errors.__all__.0'
[2017-03-01 02:59:31,086][500][<WSGIRequest: GET '/'>] Internal Server Error: /
Traceback (most recent call last):
  File "/usr/local/lib/python2.7/dist-packages/django/core/handlers/exception.py", line 39, in inner
    response = get_response(request)
  File "/usr/local/lib/python2.7/dist-packages/django/core/handlers/base.py", line 187, in _get_response
    response = self.process_exception_by_middleware(e, request)
  File "/usr/local/lib/python2.7/dist-packages/django/core/handlers/base.py", line 185, in _get_response
    response = wrapped_callback(request, *callback_args, **callback_kwargs)
  File "/root/PycharmProjects/untitled1/polls/views.py", line 30, in index
    return render(request, 'index.html', {'form': form})
  File "/usr/local/lib/python2.7/dist-packages/django/shortcuts.py", line 30, in render
    content = loader.render_to_string(template_name, context, request, using=using)
  File "/usr/local/lib/python2.7/dist-packages/django/template/loader.py", line 67, in render_to_string
    template = get_template(template_name, using=using)
  File "/usr/local/lib/python2.7/dist-packages/django/template/loader.py", line 21, in get_template
    return engine.get_template(template_name)
  File "/usr/local/lib/python2.7/dist-packages/django/template/backends/django.py", line 39, in get_template
    return Template(self.engine.get_template(template_name), self)
  File "/usr/local/lib/python2.7/dist-packages/django/template/engine.py", line 160, in get_template
    template, origin = self.find_template(template_name)
  File "/usr/local/lib/python2.7/dist-packages/django/template/engine.py", line 134, in find_template
    name, template_dirs=dirs, skip=skip,
  File "/usr/local/lib/python2.7/dist-packages/django/template/loaders/base.py", line 44, in get_template
    contents, origin, origin.template_name, self.engine,
  File "/usr/local/lib/python2.7/dist-packages/django/template/base.py", line 191, in __init__
    self.nodelist = self.compile_nodelist()
  File "/usr/local/lib/python2.7/dist-packages/django/template/base.py", line 233, in compile_nodelist
    return parser.parse()
  File "/usr/local/lib/python2.7/dist-packages/django/template/base.py", line 489, in parse
    raise self.error(token, e)
TemplateSyntaxError: Variables and attributes may not begin with underscores: 'form.errors.__all__.0'
[2017-03-01 03:02:10,241][500][<WSGIRequest: GET '/'>] Internal Server Error: /
Traceback (most recent call last):
  File "/usr/local/lib/python2.7/dist-packages/django/core/handlers/exception.py", line 39, in inner
    response = get_response(request)
  File "/usr/local/lib/python2.7/dist-packages/django/core/handlers/base.py", line 187, in _get_response
    response = self.process_exception_by_middleware(e, request)
  File "/usr/local/lib/python2.7/dist-packages/django/core/handlers/base.py", line 185, in _get_response
    response = wrapped_callback(request, *callback_args, **callback_kwargs)
  File "/root/PycharmProjects/untitled1/polls/views.py", line 30, in index
    return render(request, 'index.html', {'form': form})
  File "/usr/local/lib/python2.7/dist-packages/django/shortcuts.py", line 30, in render
    content = loader.render_to_string(template_name, context, request, using=using)
  File "/usr/local/lib/python2.7/dist-packages/django/template/loader.py", line 67, in render_to_string
    template = get_template(template_name, using=using)
  File "/usr/local/lib/python2.7/dist-packages/django/template/loader.py", line 21, in get_template
    return engine.get_template(template_name)
  File "/usr/local/lib/python2.7/dist-packages/django/template/backends/django.py", line 39, in get_template
    return Template(self.engine.get_template(template_name), self)
  File "/usr/local/lib/python2.7/dist-packages/django/template/engine.py", line 160, in get_template
    template, origin = self.find_template(template_name)
  File "/usr/local/lib/python2.7/dist-packages/django/template/engine.py", line 134, in find_template
    name, template_dirs=dirs, skip=skip,
  File "/usr/local/lib/python2.7/dist-packages/django/template/loaders/base.py", line 44, in get_template
    contents, origin, origin.template_name, self.engine,
  File "/usr/local/lib/python2.7/dist-packages/django/template/base.py", line 191, in __init__
    self.nodelist = self.compile_nodelist()
  File "/usr/local/lib/python2.7/dist-packages/django/template/base.py", line 233, in compile_nodelist
    return parser.parse()
  File "/usr/local/lib/python2.7/dist-packages/django/template/base.py", line 489, in parse
    raise self.error(token, e)
TemplateSyntaxError: Variables and attributes may not begin with underscores: 'form.errors.__all__.0'
[2017-03-01 03:04:30,008][500][<WSGIRequest: POST '/'>] Internal Server Error: /
Traceback (most recent call last):
  File "/usr/local/lib/python2.7/dist-packages/django/core/handlers/exception.py", line 39, in inner
    response = get_response(request)
  File "/usr/local/lib/python2.7/dist-packages/django/core/handlers/base.py", line 187, in _get_response
    response = self.process_exception_by_middleware(e, request)
  File "/usr/local/lib/python2.7/dist-packages/django/core/handlers/base.py", line 185, in _get_response
    response = wrapped_callback(request, *callback_args, **callback_kwargs)
  File "/root/PycharmProjects/untitled1/polls/views.py", line 30, in index
    return render(request, 'index.html', {'form': form})
  File "/usr/local/lib/python2.7/dist-packages/django/shortcuts.py", line 30, in render
    content = loader.render_to_string(template_name, context, request, using=using)
  File "/usr/local/lib/python2.7/dist-packages/django/template/loader.py", line 67, in render_to_string
    template = get_template(template_name, using=using)
  File "/usr/local/lib/python2.7/dist-packages/django/template/loader.py", line 21, in get_template
    return engine.get_template(template_name)
  File "/usr/local/lib/python2.7/dist-packages/django/template/backends/django.py", line 39, in get_template
    return Template(self.engine.get_template(template_name), self)
  File "/usr/local/lib/python2.7/dist-packages/django/template/engine.py", line 160, in get_template
    template, origin = self.find_template(template_name)
  File "/usr/local/lib/python2.7/dist-packages/django/template/engine.py", line 134, in find_template
    name, template_dirs=dirs, skip=skip,
  File "/usr/local/lib/python2.7/dist-packages/django/template/loaders/base.py", line 44, in get_template
    contents, origin, origin.template_name, self.engine,
  File "/usr/local/lib/python2.7/dist-packages/django/template/base.py", line 191, in __init__
    self.nodelist = self.compile_nodelist()
  File "/usr/local/lib/python2.7/dist-packages/django/template/base.py", line 233, in compile_nodelist
    return parser.parse()
  File "/usr/local/lib/python2.7/dist-packages/django/template/base.py", line 489, in parse
    raise self.error(token, e)
TemplateSyntaxError: Variables and attributes may not begin with underscores: 'form.errors.__all__.0'
[2017-03-01 03:07:43,519][500][<WSGIRequest: POST '/'>] Internal Server Error: /
Traceback (most recent call last):
  File "/usr/local/lib/python2.7/dist-packages/django/core/handlers/exception.py", line 39, in inner
    response = get_response(request)
  File "/usr/local/lib/python2.7/dist-packages/django/core/handlers/base.py", line 187, in _get_response
    response = self.process_exception_by_middleware(e, request)
  File "/usr/local/lib/python2.7/dist-packages/django/core/handlers/base.py", line 185, in _get_response
    response = wrapped_callback(request, *callback_args, **callback_kwargs)
  File "/root/PycharmProjects/untitled1/polls/views.py", line 17, in index
    if form.is_valid():
  File "/usr/local/lib/python2.7/dist-packages/django/forms/forms.py", line 169, in is_valid
    return self.is_bound and not self.errors
  File "/usr/local/lib/python2.7/dist-packages/django/forms/forms.py", line 161, in errors
    self.full_clean()
  File "/usr/local/lib/python2.7/dist-packages/django/forms/forms.py", line 371, in full_clean
    self._clean_form()
  File "/root/PycharmProjects/untitled1/polls/forms.py", line 78, in _clean_form
    raise ValidationError("user name or password fail!!!!")
ValidationError: [u'user name or password fail!!!!']
[2017-03-01 03:08:48,265][500][<WSGIRequest: GET '/'>] Internal Server Error: /
Traceback (most recent call last):
  File "/usr/local/lib/python2.7/dist-packages/django/core/handlers/exception.py", line 39, in inner
    response = get_response(request)
  File "/usr/local/lib/python2.7/dist-packages/django/core/handlers/base.py", line 187, in _get_response
    response = self.process_exception_by_middleware(e, request)
  File "/usr/local/lib/python2.7/dist-packages/django/core/handlers/base.py", line 185, in _get_response
    response = wrapped_callback(request, *callback_args, **callback_kwargs)
  File "/root/PycharmProjects/untitled1/polls/views.py", line 30, in index
    return render(request, 'index.html', {'form': form})
  File "/usr/local/lib/python2.7/dist-packages/django/shortcuts.py", line 30, in render
    content = loader.render_to_string(template_name, context, request, using=using)
  File "/usr/local/lib/python2.7/dist-packages/django/template/loader.py", line 67, in render_to_string
    template = get_template(template_name, using=using)
  File "/usr/local/lib/python2.7/dist-packages/django/template/loader.py", line 21, in get_template
    return engine.get_template(template_name)
  File "/usr/local/lib/python2.7/dist-packages/django/template/backends/django.py", line 39, in get_template
    return Template(self.engine.get_template(template_name), self)
  File "/usr/local/lib/python2.7/dist-packages/django/template/engine.py", line 160, in get_template
    template, origin = self.find_template(template_name)
  File "/usr/local/lib/python2.7/dist-packages/django/template/engine.py", line 134, in find_template
    name, template_dirs=dirs, skip=skip,
  File "/usr/local/lib/python2.7/dist-packages/django/template/loaders/base.py", line 44, in get_template
    contents, origin, origin.template_name, self.engine,
  File "/usr/local/lib/python2.7/dist-packages/django/template/base.py", line 191, in __init__
    self.nodelist = self.compile_nodelist()
  File "/usr/local/lib/python2.7/dist-packages/django/template/base.py", line 233, in compile_nodelist
    return parser.parse()
  File "/usr/local/lib/python2.7/dist-packages/django/template/base.py", line 489, in parse
    raise self.error(token, e)
TemplateSyntaxError: Variables and attributes may not begin with underscores: 'form.errors.__all__.0'
[2017-03-01 03:08:53,597][500][<WSGIRequest: GET '/'>] Internal Server Error: /
Traceback (most recent call last):
  File "/usr/local/lib/python2.7/dist-packages/django/core/handlers/exception.py", line 39, in inner
    response = get_response(request)
  File "/usr/local/lib/python2.7/dist-packages/django/core/handlers/base.py", line 187, in _get_response
    response = self.process_exception_by_middleware(e, request)
  File "/usr/local/lib/python2.7/dist-packages/django/core/handlers/base.py", line 185, in _get_response
    response = wrapped_callback(request, *callback_args, **callback_kwargs)
  File "/root/PycharmProjects/untitled1/polls/views.py", line 30, in index
    return render(request, 'index.html', {'form': form})
  File "/usr/local/lib/python2.7/dist-packages/django/shortcuts.py", line 30, in render
    content = loader.render_to_string(template_name, context, request, using=using)
  File "/usr/local/lib/python2.7/dist-packages/django/template/loader.py", line 67, in render_to_string
    template = get_template(template_name, using=using)
  File "/usr/local/lib/python2.7/dist-packages/django/template/loader.py", line 21, in get_template
    return engine.get_template(template_name)
  File "/usr/local/lib/python2.7/dist-packages/django/template/backends/django.py", line 39, in get_template
    return Template(self.engine.get_template(template_name), self)
  File "/usr/local/lib/python2.7/dist-packages/django/template/engine.py", line 160, in get_template
    template, origin = self.find_template(template_name)
  File "/usr/local/lib/python2.7/dist-packages/django/template/engine.py", line 134, in find_template
    name, template_dirs=dirs, skip=skip,
  File "/usr/local/lib/python2.7/dist-packages/django/template/loaders/base.py", line 44, in get_template
    contents, origin, origin.template_name, self.engine,
  File "/usr/local/lib/python2.7/dist-packages/django/template/base.py", line 191, in __init__
    self.nodelist = self.compile_nodelist()
  File "/usr/local/lib/python2.7/dist-packages/django/template/base.py", line 233, in compile_nodelist
    return parser.parse()
  File "/usr/local/lib/python2.7/dist-packages/django/template/base.py", line 489, in parse
    raise self.error(token, e)
TemplateSyntaxError: Variables and attributes may not begin with underscores: 'form.errors.__all__.0'
[2017-03-01 03:09:13,071][500][<WSGIRequest: POST '/'>] Internal Server Error: /
Traceback (most recent call last):
  File "/usr/local/lib/python2.7/dist-packages/django/core/handlers/exception.py", line 39, in inner
    response = get_response(request)
  File "/usr/local/lib/python2.7/dist-packages/django/core/handlers/base.py", line 187, in _get_response
    response = self.process_exception_by_middleware(e, request)
  File "/usr/local/lib/python2.7/dist-packages/django/core/handlers/base.py", line 185, in _get_response
    response = wrapped_callback(request, *callback_args, **callback_kwargs)
  File "/root/PycharmProjects/untitled1/polls/views.py", line 17, in index
    if form.is_valid():
  File "/usr/local/lib/python2.7/dist-packages/django/forms/forms.py", line 169, in is_valid
    return self.is_bound and not self.errors
  File "/usr/local/lib/python2.7/dist-packages/django/forms/forms.py", line 161, in errors
    self.full_clean()
  File "/usr/local/lib/python2.7/dist-packages/django/forms/forms.py", line 371, in full_clean
    self._clean_form()
  File "/root/PycharmProjects/untitled1/polls/forms.py", line 78, in _clean_form
    raise ValidationError("user name or password fail!!!!")
ValidationError: [u'user name or password fail!!!!']
[2017-03-01 04:26:41,730][500][<WSGIRequest: POST '/'>] Internal Server Error: /
Traceback (most recent call last):
  File "/usr/local/lib/python2.7/dist-packages/django/core/handlers/exception.py", line 39, in inner
    response = get_response(request)
  File "/usr/local/lib/python2.7/dist-packages/django/core/handlers/base.py", line 187, in _get_response
    response = self.process_exception_by_middleware(e, request)
  File "/usr/local/lib/python2.7/dist-packages/django/core/handlers/base.py", line 185, in _get_response
    response = wrapped_callback(request, *callback_args, **callback_kwargs)
  File "/root/PycharmProjects/untitled1/polls/views.py", line 17, in index
    if form.is_valid():
  File "/usr/local/lib/python2.7/dist-packages/django/forms/forms.py", line 169, in is_valid
    return self.is_bound and not self.errors
  File "/usr/local/lib/python2.7/dist-packages/django/forms/forms.py", line 161, in errors
    self.full_clean()
  File "/usr/local/lib/python2.7/dist-packages/django/forms/forms.py", line 371, in full_clean
    self._clean_form()
  File "/root/PycharmProjects/untitled1/polls/forms.py", line 78, in _clean_form
    raise ValidationError("user name or password fail!!!!")
ValidationError: [u'user name or password fail!!!!']
[2017-03-01 04:32:00,171][500][<WSGIRequest: POST '/'>] Internal Server Error: /
Traceback (most recent call last):
  File "/usr/local/lib/python2.7/dist-packages/django/core/handlers/exception.py", line 39, in inner
    response = get_response(request)
  File "/usr/local/lib/python2.7/dist-packages/django/core/handlers/base.py", line 187, in _get_response
    response = self.process_exception_by_middleware(e, request)
  File "/usr/local/lib/python2.7/dist-packages/django/core/handlers/base.py", line 185, in _get_response
    response = wrapped_callback(request, *callback_args, **callback_kwargs)
  File "/root/PycharmProjects/untitled1/polls/views.py", line 15, in index
    form = UserForm(request.POST)
  File "/root/PycharmProjects/untitled1/polls/forms.py", line 65, in __init__
    self.fields["host_mul_list"].widget.init
AttributeError: 'Select' object has no attribute 'init'
[2017-03-01 05:21:59,161][500][<WSGIRequest: POST '/'>] Internal Server Error: /
Traceback (most recent call last):
  File "/usr/local/lib/python2.7/dist-packages/django/core/handlers/exception.py", line 39, in inner
    response = get_response(request)
  File "/usr/local/lib/python2.7/dist-packages/django/core/handlers/base.py", line 187, in _get_response
    response = self.process_exception_by_middleware(e, request)
  File "/usr/local/lib/python2.7/dist-packages/django/core/handlers/base.py", line 185, in _get_response
    response = wrapped_callback(request, *callback_args, **callback_kwargs)
  File "/root/PycharmProjects/untitled1/polls/views.py", line 31, in index
    return render(request, 'index.html', {'form': form})
  File "/usr/local/lib/python2.7/dist-packages/django/shortcuts.py", line 30, in render
    content = loader.render_to_string(template_name, context, request, using=using)
  File "/usr/local/lib/python2.7/dist-packages/django/template/loader.py", line 67, in render_to_string
    template = get_template(template_name, using=using)
  File "/usr/local/lib/python2.7/dist-packages/django/template/loader.py", line 21, in get_template
    return engine.get_template(template_name)
  File "/usr/local/lib/python2.7/dist-packages/django/template/backends/django.py", line 39, in get_template
    return Template(self.engine.get_template(template_name), self)
  File "/usr/local/lib/python2.7/dist-packages/django/template/engine.py", line 160, in get_template
    template, origin = self.find_template(template_name)
  File "/usr/local/lib/python2.7/dist-packages/django/template/engine.py", line 134, in find_template
    name, template_dirs=dirs, skip=skip,
  File "/usr/local/lib/python2.7/dist-packages/django/template/loaders/base.py", line 44, in get_template
    contents, origin, origin.template_name, self.engine,
  File "/usr/local/lib/python2.7/dist-packages/django/template/base.py", line 191, in __init__
    self.nodelist = self.compile_nodelist()
  File "/usr/local/lib/python2.7/dist-packages/django/template/base.py", line 233, in compile_nodelist
    return parser.parse()
  File "/usr/local/lib/python2.7/dist-packages/django/template/base.py", line 489, in parse
    raise self.error(token, e)
TemplateSyntaxError: Variables and attributes may not begin with underscores: 'form.errors.__all__'
[2017-03-01 05:25:50,314][500][<WSGIRequest: POST '/'>] Internal Server Error: /
Traceback (most recent call last):
  File "/usr/local/lib/python2.7/dist-packages/django/core/handlers/exception.py", line 39, in inner
    response = get_response(request)
  File "/usr/local/lib/python2.7/dist-packages/django/core/handlers/base.py", line 187, in _get_response
    response = self.process_exception_by_middleware(e, request)
  File "/usr/local/lib/python2.7/dist-packages/django/core/handlers/base.py", line 185, in _get_response
    response = wrapped_callback(request, *callback_args, **callback_kwargs)
  File "/root/PycharmProjects/untitled1/polls/views.py", line 38, in index
    return render(request, 'index.html', {'form': form})
  File "/usr/local/lib/python2.7/dist-packages/django/shortcuts.py", line 30, in render
    content = loader.render_to_string(template_name, context, request, using=using)
  File "/usr/local/lib/python2.7/dist-packages/django/template/loader.py", line 67, in render_to_string
    template = get_template(template_name, using=using)
  File "/usr/local/lib/python2.7/dist-packages/django/template/loader.py", line 21, in get_template
    return engine.get_template(template_name)
  File "/usr/local/lib/python2.7/dist-packages/django/template/backends/django.py", line 39, in get_template
    return Template(self.engine.get_template(template_name), self)
  File "/usr/local/lib/python2.7/dist-packages/django/template/engine.py", line 160, in get_template
    template, origin = self.find_template(template_name)
  File "/usr/local/lib/python2.7/dist-packages/django/template/engine.py", line 134, in find_template
    name, template_dirs=dirs, skip=skip,
  File "/usr/local/lib/python2.7/dist-packages/django/template/loaders/base.py", line 44, in get_template
    contents, origin, origin.template_name, self.engine,
  File "/usr/local/lib/python2.7/dist-packages/django/template/base.py", line 191, in __init__
    self.nodelist = self.compile_nodelist()
  File "/usr/local/lib/python2.7/dist-packages/django/template/base.py", line 233, in compile_nodelist
    return parser.parse()
  File "/usr/local/lib/python2.7/dist-packages/django/template/base.py", line 489, in parse
    raise self.error(token, e)
TemplateSyntaxError: Variables and attributes may not begin with underscores: 'form.errors.__all__'
[2017-03-01 05:28:49,630][500][<WSGIRequest: POST '/'>] Internal Server Error: /
Traceback (most recent call last):
  File "/usr/local/lib/python2.7/dist-packages/django/core/handlers/exception.py", line 39, in inner
    response = get_response(request)
  File "/usr/local/lib/python2.7/dist-packages/django/core/handlers/base.py", line 187, in _get_response
    response = self.process_exception_by_middleware(e, request)
  File "/usr/local/lib/python2.7/dist-packages/django/core/handlers/base.py", line 185, in _get_response
    response = wrapped_callback(request, *callback_args, **callback_kwargs)
  File "/root/PycharmProjects/untitled1/polls/views.py", line 17, in index
    if form.is_valid():
  File "/usr/local/lib/python2.7/dist-packages/django/forms/forms.py", line 169, in is_valid
    return self.is_bound and not self.errors
  File "/usr/local/lib/python2.7/dist-packages/django/forms/forms.py", line 161, in errors
    self.full_clean()
  File "/usr/local/lib/python2.7/dist-packages/django/forms/forms.py", line 371, in full_clean
    self._clean_form()
  File "/root/PycharmProjects/untitled1/polls/forms.py", line 87, in _clean_form
    raise ValidationError("user name or password fail!!!!")
ValidationError: [u'user name or password fail!!!!']
[2017-03-02 00:59:23,344][404][<WSGIRequest: GET '/favicon.ico'>] Not Found: /favicon.ico
[2017-03-02 04:36:29,981][500][<WSGIRequest: GET '/server_list'>] Internal Server Error: /server_list
Traceback (most recent call last):
  File "/usr/local/lib/python2.7/dist-packages/django/core/handlers/exception.py", line 39, in inner
    response = get_response(request)
  File "/usr/local/lib/python2.7/dist-packages/django/core/handlers/base.py", line 187, in _get_response
    response = self.process_exception_by_middleware(e, request)
  File "/usr/local/lib/python2.7/dist-packages/django/core/handlers/base.py", line 185, in _get_response
    response = wrapped_callback(request, *callback_args, **callback_kwargs)
  File "/root/PycharmProjects/untitled1/polls/views.py", line 47, in server_list
    render('server_list.html',{'server_list':server_list})
  File "/usr/local/lib/python2.7/dist-packages/django/shortcuts.py", line 30, in render
    content = loader.render_to_string(template_name, context, request, using=using)
  File "/usr/local/lib/python2.7/dist-packages/django/template/loader.py", line 67, in render_to_string
    template = get_template(template_name, using=using)
  File "/usr/local/lib/python2.7/dist-packages/django/template/loader.py", line 25, in get_template
    raise TemplateDoesNotExist(template_name, chain=chain)
TemplateDoesNotExist: {'server_list': <QuerySet [<Host: server01>, <Host: server02>, <Host: server03>, <Host: server04>, <Host: server05>, <Host: server06>]>}
[2017-03-02 04:37:47,983][500][<WSGIRequest: GET '/server_list'>] Internal Server Error: /server_list
Traceback (most recent call last):
  File "/usr/local/lib/python2.7/dist-packages/django/core/handlers/exception.py", line 39, in inner
    response = get_response(request)
  File "/usr/local/lib/python2.7/dist-packages/django/core/handlers/base.py", line 198, in _get_response
    "returned None instead." % (callback.__module__, view_name)
ValueError: The view polls.views.server_list didn't return an HttpResponse object. It returned None instead.
[2017-03-02 04:43:57,573][404][<WSGIRequest: GET '/edit-server-'>] Not Found: /edit-server-
[2017-03-02 04:44:24,897][500][<WSGIRequest: GET '/edit-server-1'>] Internal Server Error: /edit-server-1
Traceback (most recent call last):
  File "/usr/local/lib/python2.7/dist-packages/django/core/handlers/exception.py", line 39, in inner
    response = get_response(request)
  File "/usr/local/lib/python2.7/dist-packages/django/core/handlers/base.py", line 198, in _get_response
    "returned None instead." % (callback.__module__, view_name)
ValueError: The view polls.views.server_detail didn't return an HttpResponse object. It returned None instead.
[2017-03-02 04:48:24,999][500][<WSGIRequest: GET '/edit-server-1'>] Internal Server Error: /edit-server-1
Traceback (most recent call last):
  File "/usr/local/lib/python2.7/dist-packages/django/core/handlers/exception.py", line 39, in inner
    response = get_response(request)
  File "/usr/local/lib/python2.7/dist-packages/django/core/handlers/base.py", line 187, in _get_response
    response = self.process_exception_by_middleware(e, request)
  File "/usr/local/lib/python2.7/dist-packages/django/core/handlers/base.py", line 185, in _get_response
    response = wrapped_callback(request, *callback_args, **callback_kwargs)
  File "/root/PycharmProjects/untitled1/polls/views.py", line 56, in server_detail
    return render(request,'server_detail.html',{'form':form})
  File "/usr/local/lib/python2.7/dist-packages/django/shortcuts.py", line 30, in render
    content = loader.render_to_string(template_name, context, request, using=using)
  File "/usr/local/lib/python2.7/dist-packages/django/template/loader.py", line 68, in render_to_string
    return template.render(context, request)
  File "/usr/local/lib/python2.7/dist-packages/django/template/backends/django.py", line 66, in render
    return self.template.render(context)
  File "/usr/local/lib/python2.7/dist-packages/django/template/base.py", line 208, in render
    return self._render(context)
  File "/usr/local/lib/python2.7/dist-packages/django/template/base.py", line 199, in _render
    return self.nodelist.render(context)
  File "/usr/local/lib/python2.7/dist-packages/django/template/base.py", line 994, in render
    bit = node.render_annotated(context)
  File "/usr/local/lib/python2.7/dist-packages/django/template/base.py", line 961, in render_annotated
    return self.render(context)
  File "/usr/local/lib/python2.7/dist-packages/django/template/defaulttags.py", line 439, in render
    url = reverse(view_name, args=args, kwargs=kwargs, current_app=current_app)
  File "/usr/local/lib/python2.7/dist-packages/django/urls/base.py", line 91, in reverse
    return force_text(iri_to_uri(resolver._reverse_with_prefix(view, prefix, *args, **kwargs)))
  File "/usr/local/lib/python2.7/dist-packages/django/urls/resolvers.py", line 392, in _reverse_with_prefix
    (lookup_view_s, args, kwargs, len(patterns), patterns)
NoReverseMatch: Reverse for 'server_detail' with arguments '()' and keyword arguments '{}' not found. 1 pattern(s) tried: ['edit-server-(?P<server_id>[0-9]+)$']
[2017-03-02 04:55:17,265][500][<WSGIRequest: POST '/edit-server-2'>] Internal Server Error: /edit-server-2
Traceback (most recent call last):
  File "/usr/local/lib/python2.7/dist-packages/django/core/handlers/exception.py", line 39, in inner
    response = get_response(request)
  File "/usr/local/lib/python2.7/dist-packages/django/core/handlers/base.py", line 187, in _get_response
    response = self.process_exception_by_middleware(e, request)
  File "/usr/local/lib/python2.7/dist-packages/django/core/handlers/base.py", line 185, in _get_response
    response = wrapped_callback(request, *callback_args, **callback_kwargs)
  File "/root/PycharmProjects/untitled1/polls/views.py", line 67, in server_detail
    return HttpResponseRedirect(reverse('server_detail'))
  File "/usr/local/lib/python2.7/dist-packages/django/urls/base.py", line 91, in reverse
    return force_text(iri_to_uri(resolver._reverse_with_prefix(view, prefix, *args, **kwargs)))
  File "/usr/local/lib/python2.7/dist-packages/django/urls/resolvers.py", line 392, in _reverse_with_prefix
    (lookup_view_s, args, kwargs, len(patterns), patterns)
NoReverseMatch: Reverse for 'server_detail' with arguments '()' and keyword arguments '{}' not found. 1 pattern(s) tried: ['edit-server-(?P<server_id>[0-9]+)$']
[2017-03-02 06:17:09,178][500][<WSGIRequest: GET '/edit-server-2'>] Internal Server Error: /edit-server-2
Traceback (most recent call last):
  File "/usr/local/lib/python2.7/dist-packages/django/core/handlers/exception.py", line 39, in inner
    response = get_response(request)
  File "/usr/local/lib/python2.7/dist-packages/django/core/handlers/base.py", line 187, in _get_response
    response = self.process_exception_by_middleware(e, request)
  File "/usr/local/lib/python2.7/dist-packages/django/core/handlers/base.py", line 185, in _get_response
    response = wrapped_callback(request, *callback_args, **callback_kwargs)
  File "/root/PycharmProjects/untitled1/polls/views.py", line 57, in server_detail
    return render(request,'server_detail.html',{'form':form,'server_id':server_id})
  File "/usr/local/lib/python2.7/dist-packages/django/shortcuts.py", line 30, in render
    content = loader.render_to_string(template_name, context, request, using=using)
  File "/usr/local/lib/python2.7/dist-packages/django/template/loader.py", line 68, in render_to_string
    return template.render(context, request)
  File "/usr/local/lib/python2.7/dist-packages/django/template/backends/django.py", line 66, in render
    return self.template.render(context)
  File "/usr/local/lib/python2.7/dist-packages/django/template/base.py", line 208, in render
    return self._render(context)
  File "/usr/local/lib/python2.7/dist-packages/django/template/base.py", line 199, in _render
    return self.nodelist.render(context)
  File "/usr/local/lib/python2.7/dist-packages/django/template/base.py", line 994, in render
    bit = node.render_annotated(context)
  File "/usr/local/lib/python2.7/dist-packages/django/template/base.py", line 961, in render_annotated
    return self.render(context)
  File "/usr/local/lib/python2.7/dist-packages/django/template/defaulttags.py", line 439, in render
    url = reverse(view_name, args=args, kwargs=kwargs, current_app=current_app)
  File "/usr/local/lib/python2.7/dist-packages/django/urls/base.py", line 91, in reverse
    return force_text(iri_to_uri(resolver._reverse_with_prefix(view, prefix, *args, **kwargs)))
  File "/usr/local/lib/python2.7/dist-packages/django/urls/resolvers.py", line 392, in _reverse_with_prefix
    (lookup_view_s, args, kwargs, len(patterns), patterns)
NoReverseMatch: Reverse for '' with arguments '()' and keyword arguments '{}' not found. 0 pattern(s) tried: []
[2017-03-02 09:22:59,194][500][<WSGIRequest: POST '/edit-server-4'>] Internal Server Error: /edit-server-4
Traceback (most recent call last):
  File "/usr/local/lib/python2.7/dist-packages/django/core/handlers/exception.py", line 39, in inner
    response = get_response(request)
  File "/usr/local/lib/python2.7/dist-packages/django/core/handlers/base.py", line 187, in _get_response
    response = self.process_exception_by_middleware(e, request)
  File "/usr/local/lib/python2.7/dist-packages/django/core/handlers/base.py", line 185, in _get_response
    response = wrapped_callback(request, *callback_args, **callback_kwargs)
  File "/root/PycharmProjects/untitled1/polls/views.py", line 67, in server_detail
    return HttpResponseRedirect(reverse('server_detail',server_obj.id))
  File "/usr/local/lib/python2.7/dist-packages/django/urls/base.py", line 91, in reverse
    return force_text(iri_to_uri(resolver._reverse_with_prefix(view, prefix, *args, **kwargs)))
  File "/usr/local/lib/python2.7/dist-packages/django/urls/resolvers.py", line 344, in _reverse_with_prefix
    self._populate()
  File "/usr/local/lib/python2.7/dist-packages/django/urls/resolvers.py", line 196, in _populate
    for pattern in reversed(self.url_patterns):
  File "/usr/local/lib/python2.7/dist-packages/django/utils/functional.py", line 35, in __get__
    res = instance.__dict__[self.name] = self.func(instance)
  File "/usr/local/lib/python2.7/dist-packages/django/urls/resolvers.py", line 322, in url_patterns
    raise ImproperlyConfigured(msg.format(name=self.urlconf_name))
ImproperlyConfigured: The included URLconf '4' does not appear to have any patterns in it. If you see valid patterns in the file then the issue is probably caused by a circular import.
[2017-03-02 09:23:52,836][500][<WSGIRequest: POST '/edit-server-1'>] Internal Server Error: /edit-server-1
Traceback (most recent call last):
  File "/usr/local/lib/python2.7/dist-packages/django/core/handlers/exception.py", line 39, in inner
    response = get_response(request)
  File "/usr/local/lib/python2.7/dist-packages/django/core/handlers/base.py", line 187, in _get_response
    response = self.process_exception_by_middleware(e, request)
  File "/usr/local/lib/python2.7/dist-packages/django/core/handlers/base.py", line 185, in _get_response
    response = wrapped_callback(request, *callback_args, **callback_kwargs)
  File "/root/PycharmProjects/untitled1/polls/views.py", line 67, in server_detail
    return HttpResponseRedirect(reverse('server_detail',server_obj.id))
  File "/usr/local/lib/python2.7/dist-packages/django/urls/base.py", line 91, in reverse
    return force_text(iri_to_uri(resolver._reverse_with_prefix(view, prefix, *args, **kwargs)))
  File "/usr/local/lib/python2.7/dist-packages/django/urls/resolvers.py", line 344, in _reverse_with_prefix
    self._populate()
  File "/usr/local/lib/python2.7/dist-packages/django/urls/resolvers.py", line 196, in _populate
    for pattern in reversed(self.url_patterns):
  File "/usr/local/lib/python2.7/dist-packages/django/utils/functional.py", line 35, in __get__
    res = instance.__dict__[self.name] = self.func(instance)
  File "/usr/local/lib/python2.7/dist-packages/django/urls/resolvers.py", line 322, in url_patterns
    raise ImproperlyConfigured(msg.format(name=self.urlconf_name))
ImproperlyConfigured: The included URLconf '1' does not appear to have any patterns in it. If you see valid patterns in the file then the issue is probably caused by a circular import.
[2017-03-06 17:16:52,217][404][<WSGIRequest: GET '/favicon.ico'>] Not Found: /favicon.ico
